Workbook

Sheet מקרא
A1: ערכת נתוני בדיקה – מסמכי מרכזי ספורט ומתנ"סים
A2: הקבצים נוצרו כדי לבדוק סוכן שמחלץ חוגים, שעות ומחירים ממסמכי Word. הגיליון "לוח_שעות" הוא ה-Ground Truth: הפלט הנכון שהסוכן אמור להפיק.
A5: קובץ | B5: מרכז | C5: סגנון המסמך | D5: מה הוא בודק
A6: 01_מרכז_ספורט_הדס_בסיסי.docx | B6: מרכז הספורט "הדס" | C6: freetext | D6: מבנה זהה כמעט למקור – טקסט חופשי, שיעורי בוקר/ערב. מקרה בסיס (happy path).
A7: 02_מרכז_ספורט_אלונים_טבלה.docx | B7: מרכז ספורט "אלונים" | C7: grid | D7: לוח השעות כטבלת Word אמיתית (ימים בעמודות, משבצות שעה בשורות). בודק חילוץ מטבלאות.
A8: 03_מרכז_כושר_נופים_מלוכלך.docx | B8: מרכז הכושר "נופים" | C8: messy | D8: קובץ 'מלוכלך': שגיאות כתיב, פורמטי שעה מעורבים, מדריכים חסרים, כפילות, שיעור מבוטל, מחירים בפורמטים שונים.
A9: 04_Neve_Sport_Center_bilingual.docx | B9: Neve Sport Center / מרכז הספורט "נווה" | C9: bilingual | D9: דו-לשוני עברית/אנגלית, שעות בפורמט 12 שעות (AM/PM), שמות ימים באנגלית. בודק זיהוי שפה ופורמט שעה.
A10: 05_מרכז_ספורט_מעיין_לפי_חוג.docx | B10: מרכז ספורט "מעיין" | C10: bycourse | D10: הלוח מאורגן לפי חוג ולא לפי יום (כל חוג = כותרת + רשימת מפגשים). בודק צורת חילוץ הפוכה.
A11: 06_מרכז_ספורט_גלים_מקרי_קצה.docx | B11: מרכז הספורט "גלים" | C11: edge | D11: מקרי קצה: שני סניפים, שעות קיץ/חורף, תאריכי התחלה, סגירות חג, מגבלות קיבולת, שני מדריכים, התנגשות אולמות.
A13: מילון עמודות – גיליון "לוח_שעות"
A14: יום / שעת_התחלה / שעת_סיום | B14: הערך המנורמל שהסוכן אמור להחזיר (שעה בפורמט HH:MM, יום בעברית).
A15: יום_בקובץ / שעה_בקובץ / שם_בקובץ | B15: הצורה הגולמית שבה הערך מופיע במסמך המקור (למשל "9.00", "7:40 AM", "פילטיס").
A16: משך_דקות / תקופה | B16: שדות מחושבים בנוסחה מתוך שעות ההתחלה והסיום.
A17: מלכודת_בדיקה | B17: תיאור הקושי המכוון בשורה. שורה ריקה = מקרה פשוט.
A19: שים לב | B19: כל השמות, הכתובות, הטלפונים והמחירים בדויים ונועדו לבדיקה בלבד. הגיליון "מקור_פענוח_גולמי" הוא פענוח ידני של הקובץ שהעלית ודורש אימות – הוא אינו Ground Truth.

Sheet לוח_שעות
A1: קובץ_מקור | B1: מזהה_מרכז | C1: שם_המרכז | D1: יום | E1: יום_בקובץ | F1: שעת_התחלה | G1: שעת_סיום | H1: משך_דקות | I1: תקופה | J1: שעה_בקובץ | K1: שם_החוג | L1: שם_בקובץ | M1: שם_באנגלית | N1: מדריך | O1: אולם | P1: קהל_יעד | Q1: הערות | R1: מלכודת_בדיקה
A2: 01_מרכז_ספורט_הדס_בסיסי.docx | B2: hadas | C2: מרכז הספורט "הדס" | D2: ראשון | E2: ראשון | F2: 08:00 | G2: 08:50 | H2: =IFERROR((TIMEVALUE(G2)-TIMEVALUE(F2))*1440,"") -> 50 | I2: =IF(F2<"13:00","בוקר","ערב") -> בוקר | J2: 08:00-08:50 | K2: התעמלות מתונה | L2: התעמלות מתונה | N2: אורלי | O2: אולם ספורט | P2: נשים
A3: 01_מרכז_ספורט_הדס_בסיסי.docx | B3: hadas | C3: מרכז הספורט "הדס" | D3: ראשון | E3: ראשון | F3: 09:00 | G3: 09:50 | H3: =IFERROR((TIMEVALUE(G3)-TIMEVALUE(F3))*1440,"") -> 50 | I3: =IF(F3<"13:00","בוקר","ערב") -> בוקר | J3: 09:00-09:50 | K3: עיצוב וחיזוק | L3: עיצוב וחיזוק | N3: מיכל | O3: אולם ספורט | P3: גם לגברים
A4: 01_מרכז_ספורט_הדס_בסיסי.docx | B4: hadas | C4: מרכז הספורט "הדס" | D4: ראשון | E4: ראשון | F4: 18:00 | G4: 18:50 | H4: =IFERROR((TIMEVALUE(G4)-TIMEVALUE(F4))*1440,"") -> 50 | I4: =IF(F4<"13:00","בוקר","ערב") -> ערב | J4: 18:00-18:50 | K4: פילאטיס | L4: פילאטיס | N4: שירה | O4: סטודיו תחתון | P4: גם לגברים
A5: 01_מרכז_ספורט_הדס_בסיסי.docx | B5: hadas | C5: מרכז הספורט "הדס" | D5: ראשון | E5: ראשון | F5: 19:00 | G5: 19:50 | H5: =IFERROR((TIMEVALUE(G5)-TIMEVALUE(F5))*1440,"") -> 50 | I5: =IF(F5<"13:00","בוקר","ערב") -> ערב | J5: 19:00-19:50 | K5: זומבה | L5: זומבה | N5: נועה | O5: סטודיו עליון | P5: נשים
A6: 01_מרכז_ספורט_הדס_בסיסי.docx | B6: hadas | C6: מרכז הספורט "הדס" | D6: שני | E6: שני | F6: 07:40 | G6: 08:30 | H6: =IFERROR((TIMEVALUE(G6)-TIMEVALUE(F6))*1440,"") -> 50 | I6: =IF(F6<"13:00","בוקר","ערב") -> בוקר | J6: 07:40-08:30 | K6: התעמלות מתונה | L6: התעמלות מתונה | N6: אורלי | O6: אולם ספורט | P6: נשים
A7: 01_מרכז_ספורט_הדס_בסיסי.docx | B7: hadas | C7: מרכז הספורט "הדס" | D7: שני | E7: שני | F7: 09:00 | G7: 09:50 | H7: =IFERROR((TIMEVALUE(G7)-TIMEVALUE(F7))*1440,"") -> 50 | I7: =IF(F7<"13:00","בוקר","ערב") -> בוקר | J7: 09:00-09:50 | K7: יוגה | L7: יוגה | N7: תניא | O7: ספורט כייף | P7: גם לגברים
A8: 01_מרכז_ספורט_הדס_בסיסי.docx | B8: hadas | C8: מרכז הספורט "הדס" | D8: שני | E8: שני | F8: 17:30 | G8: 18:20 | H8: =IFERROR((TIMEVALUE(G8)-TIMEVALUE(F8))*1440,"") -> 50 | I8: =IF(F8<"13:00","בוקר","ערב") -> ערב | J8: 17:30-18:20 | K8: עיצוב קל | L8: עיצוב קל | N8: דנה | O8: סטודיו תחתון | P8: נשים
A9: 01_מרכז_ספורט_הדס_בסיסי.docx | B9: hadas | C9: מרכז הספורט "הדס" | D9: שני | E9: שני | F9: 19:00 | G9: 19:50 | H9: =IFERROR((TIMEVALUE(G9)-TIMEVALUE(F9))*1440,"") -> 50 | I9: =IF(F9<"13:00","בוקר","ערב") -> ערב | J9: 19:00-19:50 | K9: ספינינג | L9: ספינינג | N9: גל | O9: חדר ספינינג | P9: גם לגברים
A10: 01_מרכז_ספורט_הדס_בסיסי.docx | B10: hadas | C10: מרכז הספורט "הדס" | D10: שלישי | E10: שלישי | F10: 08:30 | G10: 09:20 | H10: =IFERROR((TIMEVALUE(G10)-TIMEVALUE(F10))*1440,"") -> 50 | I10: =IF(F10<"13:00","בוקר","ערב") -> בוקר | J10: 08:30-09:20 | K10: פילאטיס | L10: פילאטיס | N10: שירה | O10: סטודיו תחתון | P10: גם לגברים
A11: 01_מרכז_ספורט_הדס_בסיסי.docx | B11: hadas | C11: מרכז הספורט "הדס" | D11: שלישי | E11: שלישי | F11: 18:30 | G11: 19:20 | H11: =IFERROR((TIMEVALUE(G11)-TIMEVALUE(F11))*1440,"") -> 50 | I11: =IF(F11<"13:00","בוקר","ערב") -> ערב | J11: 18:30-19:20 | K11: אימון פונקציונלי | L11: אימון פונקציונלי | N11: אבי | O11: אולם ספורט | P11: גם לגברים
A12: 01_מרכז_ספורט_הדס_בסיסי.docx | B12: hadas | C12: מרכז הספורט "הדס" | D12: רביעי | E12: רביעי | F12: 09:15 | G12: 10:00 | H12: =IFERROR((TIMEVALUE(G12)-TIMEVALUE(F12))*1440,"") -> 45 | I12: =IF(F12<"13:00","בוקר","ערב") -> בוקר | J12: 09:15-10:00 | K12: התעמלות במים | L12: התעמלות במים | N12: זויה | O12: בריכה | P12: נשים
A13: 01_מרכז_ספורט_הדס_בסיסי.docx | B13: hadas | C13: מרכז הספורט "הדס" | D13: רביעי | E13: רביעי | F13: 19:10 | G13: 20:00 | H13: =IFERROR((TIMEVALUE(G13)-TIMEVALUE(F13))*1440,"") -> 50 | I13: =IF(F13<"13:00","בוקר","ערב") -> ערב | J13: 19:10-20:00 | K13: יוגה | L13: יוגה | N13: משה | O13: ספורט כייף | P13: גם לגברים
... A27: 02_מרכז_ספורט_אלונים_טבלה.docx | B27: alonim | C27: מרכז ספורט "אלונים" | D27: רביעי | E27: רביעי | F27: 08:00 | G27: 08:55 | H27: =IFERROR((TIMEVALUE(G27)-TIMEVALUE(F27))*1440,"") -> 55 | I27: =IF(F27<"13:00","בוקר","ערב") -> בוקר | J27: 08:00-08:55 | K27: התעמלות מתונה | L27: התעמלות מתונה | N27: חנה | O27: אולם | P27: נשים
A28: 02_מרכז_ספורט_אלונים_טבלה.docx | B28: alonim | C28: מרכז ספורט "אלונים" | D28: רביעי | E28: רביעי | F28: 18:40 | G28: 19:35 | H28: =IFERROR((TIMEVALUE(G28)-TIMEVALUE(F28))*1440,"") -> 55 | I28: =IF(F28<"13:00","בוקר","ערב") -> ערב | J28: 18:40-19:35 | K28: TRX | L28: TRX | N28: אבי | O28: חדר כושר | P28: גם לגברים | R28: שם חוג לועזי בתוך טקסט עברי
A29: 02_מרכז_ספורט_אלונים_טבלה.docx | B29: alonim | C29: מרכז ספורט "אלונים" | D29: חמישי | E29: חמישי | F29: 09:10 | G29: 09:55 | H29: =IFERROR((TIMEVALUE(G29)-TIMEVALUE(F29))*1440,"") -> 45 | I29: =IF(F29<"13:00","בוקר","ערב") -> בוקר | J29: 09:10-09:55 | K29: אקווה אירובי | L29: אקווה אירובי | N29: זויה | O29: בריכה | P29: נשים
A30: 02_מרכז_ספורט_אלונים_טבלה.docx | B30: alonim | C30: מרכז ספורט "אלונים" | D30: חמישי | E30: חמישי | F30: 19:50 | G30: 21:00 | H30: =IFERROR((TIMEVALUE(G30)-TIMEVALUE(F30))*1440,"") -> 70 | I30: =IF(F30<"13:00","בוקר","ערב") -> ערב | J30: 19:50-21:00 | K30: ריקודי עם | L30: ריקודי עם | N30: יוסי | O30: אולם | P30: גם לגברים | R30: שיעור באורך חריג (70 דק')
A31: 02_מרכז_ספורט_אלונים_טבלה.docx | B31: alonim | C31: מרכז ספורט "אלונים" | D31: שישי | E31: שישי | F31: 08:00 | G31: 08:55 | H31: =IFERROR((TIMEVALUE(G31)-TIMEVALUE(F31))*1440,"") -> 55 | I31: =IF(F31<"13:00","בוקר","ערב") -> בוקר | J31: 08:00-08:55 | K31: פילאטיס | L31: פילאטיס | N31: קרן | O31: סטודיו א' | P31: גם לגברים
A32: 03_מרכז_כושר_נופים_מלוכלך.docx | B32: nofim | C32: מרכז הכושר "נופים" | D32: ראשון | E32: ראשון | F32: 08:00 | H32: =IFERROR((TIMEVALUE(G32)-TIMEVALUE(F32))*1440,"") | I32: =IF(F32<"13:00","בוקר","ערב") -> בוקר | J32: 8.00 | K32: התעמלות מתונה | L32: התעמלות מתונהה | N32: רחלי | O32: אולם ספורט | P32: נשים | R32: אין שעת סיום
A33: 03_מרכז_כושר_נופים_מלוכלך.docx | B33: nofim | C33: מרכז הכושר "נופים" | D33: ראשון | E33: ראשון | F33: 09:00 | G33: 09:50 | H33: =IFERROR((TIMEVALUE(G33)-TIMEVALUE(F33))*1440,"") -> 50 | I33: =IF(F33<"13:00","בוקר","ערב") -> בוקר | J33: 09:00 | K33: פילאטיס | L33: פילטיס | N33: ליאת | O33: סטודיו תחתון | P33: נשים | R33: שגיאת כתיב בשם החוג (פילטיס)
A34: 03_מרכז_כושר_נופים_מלוכלך.docx | B34: nofim | C34: מרכז הכושר "נופים" | D34: ראשון | E34: ראשון | F34: 18:00 | G34: 19:00 | H34: =IFERROR((TIMEVALUE(G34)-TIMEVALUE(F34))*1440,"") -> 60 | I34: =IF(F34<"13:00","בוקר","ערב") -> ערב | J34: 18:00-19:00 | K34: עיצוב וחיזוק | L34: עיצוב וחיזוק | O34: סטודיו תחתון | P34: נשים | R34: שם מדריכה חסר – 'יתעדכן'
A35: 03_מרכז_כושר_נופים_מלוכלך.docx | B35: nofim | C35: מרכז הכושר "נופים" | D35: שני | E35: שני | F35: 07:40 | H35: =IFERROR((TIMEVALUE(G35)-TIMEVALUE(F35))*1440,"") | I35: =IF(F35<"13:00","בוקר","ערב") -> בוקר | J35: 7:40 | K35: התעמלות מתונה | L35: התעמלות מתונה | N35: רחלי | O35: אולם ספורט | P35: נשים | R35: רווחים כפולים בשורה
A36: 03_מרכז_כושר_נופים_מלוכלך.docx | B36: nofim | C36: מרכז הכושר "נופים" | D36: שני | E36: שני | F36: 19:10 | G36: 20:00 | H36: =IFERROR((TIMEVALUE(G36)-TIMEVALUE(F36))*1440,"") -> 50 | I36: =IF(F36<"13:00","בוקר","ערב") -> ערב | J36: 19.10 | K36: זומבה | L36: זומבה | N36: סיון | O36: סטודיו עליון | P36: נשים | R36: פורמט שעה עם נקודה
A37: 03_מרכז_כושר_נופים_מלוכלך.docx | B37: nofim | C37: מרכז הכושר "נופים" | D37: שני | E37: שני | F37: 20:10 | G37: 21:00 | H37: =IFERROR((TIMEVALUE(G37)-TIMEVALUE(F37))*1440,"") -> 50 | I37: =IF(F37<"13:00","בוקר","ערב") -> ערב | J37: 20:10 | K37: יוגה | L37: יוגה - בוטל!! | N37: משה | O37: ספורט כייף | P37: גם לגברים | Q37: מבוטל עד להודעה חדשה | R37: שיעור מבוטל – לא אמור להיכנס ללוח פעיל
A38: 03_מרכז_כושר_נופים_מלוכלך.docx | B38: nofim | C38: מרכז הכושר "נופים" | D38: שלישי | E38: שלישי | F38: 08:30 | G38: 09:20 | H38: =IFERROR((TIMEVALUE(G38)-TIMEVALUE(F38))*1440,"") -> 50 | I38: =IF(F38<"13:00","בוקר","ערב") -> בוקר | J38: 08.30 | K38: ספינינג | L38: ספינינג | N38: גל | O38: חדר ספינינג | P38: גם לגברים
A39: 03_מרכז_כושר_נופים_מלוכלך.docx | B39: nofim | C39: מרכז הכושר "נופים" | D39: שלישי | E39: שלישי | F39: 17:00 | G39: 18:00 | H39: =IFERROR((TIMEVALUE(G39)-TIMEVALUE(F39))*1440,"") -> 60 | I39: =IF(F39<"13:00","בוקר","ערב") -> ערב | J39: 17:00 – 18:00 | K39: עיצוב קל | L39: עיצוב קל | N39: ליאת | O39: סטודיו תחתון | P39: נשים | R39: טווח שעות עם מקף ארוך (–)
A40: 03_מרכז_כושר_נופים_מלוכלך.docx | B40: nofim | C40: מרכז הכושר "נופים" | D40: שלישי | E40: שלישי | F40: 17:00 | G40: 18:00 | H40: =IFERROR((TIMEVALUE(G40)-TIMEVALUE(F40))*1440,"") -> 60 | I40: =IF(F40<"13:00","בוקר","ערב") -> ערב | J40: 17:00-18:00 | K40: עיצוב קל | L40: עיצוב קל | N40: ליאת | O40: סטודיו תחתון | P40: נשים | Q40: שורה כפולה בקובץ המקור | R40: כפילות מכוונת – יש לזהות ולאחד
A41: 03_מרכז_כושר_נופים_מלוכלך.docx | B41: nofim | C41: מרכז הכושר "נופים" | D41: רביעי | E41: רביעי | F41: 09:15 | G41: 10:00 | H41: =IFERROR((TIMEVALUE(G41)-TIMEVALUE(F41))*1440,"") -> 45 | I41: =IF(F41<"13:00","בוקר","ערב") -> בוקר | J41: 09:15 | K41: התעמלות במים | L41: התעמלות במים | N41: זויה | O41: בריכה | P41: נשים
A42: 03_מרכז_כושר_נופים_מלוכלך.docx | B42: nofim | C42: מרכז הכושר "נופים" | D42: רביעי | E42: רביעי | F42: 18:30 | G42: 19:30 | H42: =IFERROR((TIMEVALUE(G42)-TIMEVALUE(F42))*1440,"") -> 60 | I42: =IF(F42<"13:00","בוקר","ערב") -> ערב | J42: 18:30 | K42: קיקבוקס | L42: קיקבוקס | N42: אבי | P42: גם לגברים | R42: אולם לא צוין
A43: 03_מרכז_כושר_נופים_מלוכלך.docx | B43: nofim | C43: מרכז הכושר "נופים" | D43: חמישי | E43: חמישי | F43: 09:00 | G43: 10:00 | H43: =IFERROR((TIMEVALUE(G43)-TIMEVALUE(F43))*1440,"") -> 60 | I43: =IF(F43<"13:00","בוקר","ערב") -> בוקר | J43: 9:00 | K43: פלדנקרייז | L43: פלדנקרייז | N43: הילה | O43: ספורט כייף | P43: גם לגברים
A44: 03_מרכז_כושר_נופים_מלוכלך.docx | B44: nofim | C44: מרכז הכושר "נופים" | D44: חמישי | E44: חמישי | F44: 19:00 | G44: 20:00 | H44: =IFERROR((TIMEVALUE(G44)-TIMEVALUE(F44))*1440,"") -> 60 | I44: =IF(F44<"13:00","בוקר","ערב") -> ערב | J44: 7:00 בערב | K44: פילאטיס | L44: פילאטיס | N44: ליאת | O44: סטודיו תחתון | P44: גם לגברים
A45: 03_מרכז_כושר_נופים_מלוכלך.docx | B45: nofim | C45: מרכז הכושר "נופים" | D45: שישי | E45: שישי | F45: 08:30 | G45: 09:20 | H45: =IFERROR((TIMEVALUE(G45)-TIMEVALUE(F45))*1440,"") -> 50 | I45: =IF(F45<"13:00","בוקר","ערב") -> בוקר | J45: 08:30 | K45: עיצוב דינמי | L45: עיצוב דינמי | N45: סיון | O45: סטודיו עליון | P45: נשים
A46: 04_Neve_Sport_Center_bilingual.docx | B46: neve | C46: Neve Sport Center / מרכז הספורט "נווה" | D46: ראשון | E46: Sunday | F46: 07:40 | G46: 08:30 | H46: =IFERROR((TIMEVALUE(G46)-TIMEVALUE(F46))*1440,"") -> 50 | I46: =IF(F46<"13:00","בוקר","ערב") -> בוקר | J46: 7:40 AM - 8:30 AM | K46: התעמלות מתונה | L46: Gentle Gymnastics / התעמלות מתונה | M46: Gentle Gymnastics | N46: Ora | O46: Main Hall | P46: Women only | R46: שעה בפורמט 12 שעות
A47: 04_Neve_Sport_Center_bilingual.docx | B47: neve | C47: Neve Sport Center / מרכז הספורט "נווה" | D47: ראשון | E47: Sunday | F47: 09:00 | G47: 09:50 | H47: =IFERROR((TIMEVALUE(G47)-TIMEVALUE(F47))*1440,"") -> 50 | I47: =IF(F47<"13:00","בוקר","ערב") -> בוקר | J47: 9:00 AM - 9:50 AM | K47: פילאטיס | L47: Pilates / פילאטיס | M47: Pilates | N47: Revital | O47: Studio 1 | P47: Mixed
A48: 04_Neve_Sport_Center_bilingual.docx | B48: neve | C48: Neve Sport Center / מרכז הספורט "נווה" | D48: ראשון | E48: Sunday | F48: 18:05 | G48: 18:55 | H48: =IFERROR((TIMEVALUE(G48)-TIMEVALUE(F48))*1440,"") -> 50 | I48: =IF(F48<"13:00","בוקר","ערב") -> ערב | J48: 6:05 PM - 6:55 PM | K48: יוגה זורמת | L48: Yoga Flow / יוגה זורמת | M48: Yoga Flow | N48: Tania | O48: Studio 2 | P48: Mixed
A49: 04_Neve_Sport_Center_bilingual.docx | B49: neve | C49: Neve Sport Center / מרכז הספורט "נווה" | D49: שני | E49: Monday | F49: 08:30 | G49: 09:20 | H49: =IFERROR((TIMEVALUE(G49)-TIMEVALUE(F49))*1440,"") -> 50 | I49: =IF(F49<"13:00","בוקר","ערב") -> בוקר | J49: 8:30 AM - 9:20 AM | K49: ספינינג | L49: Spinning / ספינינג | M49: Spinning | N49: Gal | O49: Spinning Room | P49: Mixed | Q49: Beginners briefing 8:15-8:30 | R49: הערה על תדריך למתחילים בתוך התא
A50: 04_Neve_Sport_Center_bilingual.docx | B50: neve | C50: Neve Sport Center / מרכז הספורט "נווה" | D50: שני | E50: Monday | F50: 19:10 | G50: 20:00 | H50: =IFERROR((TIMEVALUE(G50)-TIMEVALUE(F50))*1440,"") -> 50 | I50: =IF(F50<"13:00","בוקר","ערב") -> ערב | J50: 7:10 PM - 8:00 PM | K50: זומבה | L50: Zumba / זומבה | M50: Zumba | N50: Indy | O50: Studio 2 | P50: Women only
A51: 04_Neve_Sport_Center_bilingual.docx | B51: neve | C51: Neve Sport Center / מרכז הספורט "נווה" | D51: שלישי | E51: Tuesday | F51: 09:15 | G51: 10:00 | H51: =IFERROR((TIMEVALUE(G51)-TIMEVALUE(F51))*1440,"") -> 45 | I51: =IF(F51<"13:00","בוקר","ערב") -> בוקר | J51: 9:15 AM - 10:00 AM | K51: התעמלות במים | L51: Aqua Aerobics / התעמלות במים | M51: Aqua Aerobics | N51: Zoya | O51: Pool | P51: Women only
A52: 04_Neve_Sport_Center_bilingual.docx | B52: neve | C52: Neve Sport Center / מרכז הספורט "נווה" | D52: שלישי | E52: Tuesday | F52: 18:30 | G52: 19:20 | H52: =IFERROR((TIMEVALUE(G52)-TIMEVALUE(F52))*1440,"") -> 50 | I52: =IF(F52<"13:00","בוקר","ערב") -> ערב | J52: 6:30 PM - 7:20 PM | K52: אימון עצימות גבוהה | L52: HIIT / אימון עצימות גבוהה | M52: HIIT | N52: Avi | O52: Main Hall | P52: Mixed | Q52: Age 16+ | R52: הגבלת גיל באנגלית
A53: 04_Neve_Sport_Center_bilingual.docx | B53: neve | C53: Neve Sport Center / מרכז הספורט "נווה" | D53: רביעי | E53: Wednesday | F53: 08:30 | G53: 09:20 | H53: =IFERROR((TIMEVALUE(G53)-TIMEVALUE(F53))*1440,"") -> 50 | I53: =IF(F53<"13:00","בוקר","ערב") -> בוקר | J53: 8:30 AM - 9:20 AM | K53: פילאטיס | L53: Pilates / פילאטיס | M53: Pilates | N53: Revital | O53: Studio 1 | P53: Mixed
...

Sheet בדיקות_צפויות
A1: קובץ_מקור | B1: סגנון | C1: סה"כ_שיעורים | D1: שיעורי_בוקר | E1: שיעורי_ערב | F1: ללא_מדריך | G1: ללא_אולם | H1: ללא_שעת_סיום | I1: שורות_עם_מלכודת
A2: 01_מרכז_ספורט_הדס_בסיסי.docx | B2: freetext | C2: =COUNTIF(לוח_שעות!$A$2:$A$87,$A2) -> 15 | D2: =COUNTIFS(לוח_שעות!$A$2:$A$87,$A2,לוח_שעות!$I$2:$I$87,"בוקר") -> 8 | E2: =COUNTIFS(לוח_שעות!$A$2:$A$87,$A2,לוח_שעות!$I$2:$I$87,"ערב") -> 7 | F2: =COUNTIFS(לוח_שעות!$A$2:$A$87,$A2,לוח_שעות!$N$2:$N$87,"") -> 0 | G2: =COUNTIFS(לוח_שעות!$A$2:$A$87,$A2,לוח_שעות!$O$2:$O$87,"") -> 0 | H2: =COUNTIFS(לוח_שעות!$A$2:$A$87,$A2,לוח_שעות!$G$2:$G$87,"") -> 0 | I2: =COUNTIFS(לוח_שעות!$A$2:$A$87,$A2,לוח_שעות!$R$2:$R$87,"<>") -> 0
A3: 02_מרכז_ספורט_אלונים_טבלה.docx | B3: grid | C3: =COUNTIF(לוח_שעות!$A$2:$A$87,$A3) -> 15 | D3: =COUNTIFS(לוח_שעות!$A$2:$A$87,$A3,לוח_שעות!$I$2:$I$87,"בוקר") -> 8 | E3: =COUNTIFS(לוח_שעות!$A$2:$A$87,$A3,לוח_שעות!$I$2:$I$87,"ערב") -> 7 | F3: =COUNTIFS(לוח_שעות!$A$2:$A$87,$A3,לוח_שעות!$N$2:$N$87,"") -> 0 | G3: =COUNTIFS(לוח_שעות!$A$2:$A$87,$A3,לוח_שעות!$O$2:$O$87,"") -> 0 | H3: =COUNTIFS(לוח_שעות!$A$2:$A$87,$A3,לוח_שעות!$G$2:$G$87,"") -> 0 | I3: =COUNTIFS(לוח_שעות!$A$2:$A$87,$A3,לוח_שעות!$R$2:$R$87,"<>") -> 2
A4: 03_מרכז_כושר_נופים_מלוכלך.docx | B4: messy | C4: =COUNTIF(לוח_שעות!$A$2:$A$87,$A4) -> 14 | D4: =COUNTIFS(לוח_שעות!$A$2:$A$87,$A4,לוח_שעות!$I$2:$I$87,"בוקר") -> 7 | E4: =COUNTIFS(לוח_שעות!$A$2:$A$87,$A4,לוח_שעות!$I$2:$I$87,"ערב") -> 7 | F4: =COUNTIFS(לוח_שעות!$A$2:$A$87,$A4,לוח_שעות!$N$2:$N$87,"") -> 1 | G4: =COUNTIFS(לוח_שעות!$A$2:$A$87,$A4,לוח_שעות!$O$2:$O$87,"") -> 1 | H4: =COUNTIFS(לוח_שעות!$A$2:$A$87,$A4,לוח_שעות!$G$2:$G$87,"") -> 2 | I4: =COUNTIFS(לוח_שעות!$A$2:$A$87,$A4,לוח_שעות!$R$2:$R$87,"<>") -> 9
A5: 04_Neve_Sport_Center_bilingual.docx | B5: bilingual | C5: =COUNTIF(לוח_שעות!$A$2:$A$87,$A5) -> 12 | D5: =COUNTIFS(לוח_שעות!$A$2:$A$87,$A5,לוח_שעות!$I$2:$I$87,"בוקר") -> 7 | E5: =COUNTIFS(לוח_שעות!$A$2:$A$87,$A5,לוח_שעות!$I$2:$I$87,"ערב") -> 5 | F5: =COUNTIFS(לוח_שעות!$A$2:$A$87,$A5,לוח_שעות!$N$2:$N$87,"") -> 0 | G5: =COUNTIFS(לוח_שעות!$A$2:$A$87,$A5,לוח_שעות!$O$2:$O$87,"") -> 0 | H5: =COUNTIFS(לוח_שעות!$A$2:$A$87,$A5,לוח_שעות!$G$2:$G$87,"") -> 0 | I5: =COUNTIFS(לוח_שעות!$A$2:$A$87,$A5,לוח_שעות!$R$2:$R$87,"<>") -> 3
A6: 05_מרכז_ספורט_מעיין_לפי_חוג.docx | B6: bycourse | C6: =COUNTIF(לוח_שעות!$A$2:$A$87,$A6) -> 14 | D6: =COUNTIFS(לוח_שעות!$A$2:$A$87,$A6,לוח_שעות!$I$2:$I$87,"בוקר") -> 7 | E6: =COUNTIFS(לוח_שעות!$A$2:$A$87,$A6,לוח_שעות!$I$2:$I$87,"ערב") -> 7 | F6: =COUNTIFS(לוח_שעות!$A$2:$A$87,$A6,לוח_שעות!$N$2:$N$87,"") -> 0 | G6: =COUNTIFS(לוח_שעות!$A$2:$A$87,$A6,לוח_שעות!$O$2:$O$87,"") -> 0 | H6: =COUNTIFS(לוח_שעות!$A$2:$A$87,$A6,לוח_שעות!$G$2:$G$87,"") -> 0 | I6: =COUNTIFS(לוח_שעות!$A$2:$A$87,$A6,לוח_שעות!$R$2:$R$87,"<>") -> 2
A7: 06_מרכז_ספורט_גלים_מקרי_קצה.docx | B7: edge | C7: =COUNTIF(לוח_שעות!$A$2:$A$87,$A7) -> 16 | D7: =COUNTIFS(לוח_שעות!$A$2:$A$87,$A7,לוח_שעות!$I$2:$I$87,"בוקר") -> 8 | E7: =COUNTIFS(לוח_שעות!$A$2:$A$87,$A7,לוח_שעות!$I$2:$I$87,"ערב") -> 8 | F7: =COUNTIFS(לוח_שעות!$A$2:$A$87,$A7,לוח_שעות!$N$2:$N$87,"") -> 1 | G7: =COUNTIFS(לוח_שעות!$A$2:$A$87,$A7,לוח_שעות!$O$2:$O$87,"") -> 1 | H7: =COUNTIFS(לוח_שעות!$A$2:$A$87,$A7,לוח_שעות!$G$2:$G$87,"") -> 0 | I7: =COUNTIFS(לוח_שעות!$A$2:$A$87,$A7,לוח_שעות!$R$2:$R$87,"<>") -> 11
A8: סה"כ | C8: =SUM(C2:C7) -> 86 | D8: =SUM(D2:D7) -> 45 | E8: =SUM(E2:E7) -> 41 | F8: =SUM(F2:F7) -> 2 | G8: =SUM(G2:G7) -> 2 | H8: =SUM(H2:H7) -> 2 | I8: =SUM(I2:I7) -> 27
A10: כל המספרים כאן מחושבים בנוסחאות מתוך גיליון "לוח_שעות" – אפשר להשוות אליהם את פלט הסוכן.

Sheet מחירונים
A1: קובץ_מקור | B1: שם_המרכז | C1: פריט | D1: מחיר_כפי_שמופיע | E1: הערות
A2: 01_מרכז_ספורט_הדס_בסיסי.docx | B2: מרכז הספורט "הדס" | C2: כניסה חד פעמית | D2: 65 ₪ | E2: ילד/סטודנט/חייל – 58 ₪
A3: 01_מרכז_ספורט_הדס_בסיסי.docx | B3: מרכז הספורט "הדס" | C3: כרטיסייה ל-12 כניסות | D3: 600 ₪ | E3: גמלאי/סטודנט/חייל – 540 ₪
A4: 01_מרכז_ספורט_הדס_בסיסי.docx | B4: מרכז הספורט "הדס" | C4: מנוי לחודש אחד בלבד | D4: 319 ₪
A5: 01_מרכז_ספורט_הדס_בסיסי.docx | B5: מרכז הספורט "הדס" | C5: מנוי רץ בהוראת קבע (מינימום 6 חודשים) | D5: 279 ₪ לחודש | E5: גמלאי/סטודנט/חייל/נכה – 269 ₪
A6: 01_מרכז_ספורט_הדס_בסיסי.docx | B6: מרכז הספורט "הדס" | C6: חדר כושר נוער (גילאי 12-16) | D6: 199 ₪ לחודש | E6: ימים ב', ד' בשעות 16:30-17:30
A7: 02_מרכז_ספורט_אלונים_טבלה.docx | B7: מרכז ספורט "אלונים" | C7: כניסה חד פעמית | D7: 55 ₪
A8: 02_מרכז_ספורט_אלונים_טבלה.docx | B8: מרכז ספורט "אלונים" | C8: כרטיסייה ל-10 כניסות | D8: 480 ₪ | E8: בתוקף לשנה מיום הרכישה
A9: 02_מרכז_ספורט_אלונים_טבלה.docx | B9: מרכז ספורט "אלונים" | C9: מנוי חודשי | D9: 289 ₪
A10: 02_מרכז_ספורט_אלונים_טבלה.docx | B10: מרכז ספורט "אלונים" | C10: מנוי שנתי מראש | D10: 2,690 ₪ | E10: כולל 2 חודשי הקפאה
A11: 02_מרכז_ספורט_אלונים_טבלה.docx | B11: מרכז ספורט "אלונים" | C11: מנוי זוגי בהוראת קבע | D11: 469 ₪ לחודש | E11: מינימום 3 חודשים
A12: 03_מרכז_כושר_נופים_מלוכלך.docx | B12: מרכז הכושר "נופים" | C12: כניסה חד פעמית | D12: 60 ש"ח | E12: סטודנט 55
A13: 03_מרכז_כושר_נופים_מלוכלך.docx | B13: מרכז הכושר "נופים" | C13: כרטיסיה 12 כניסות | D13: ₪570
A14: 03_מרכז_כושר_נופים_מלוכלך.docx | B14: מרכז הכושר "נופים" | C14: מנוי חודשי | D14: 299 | E14: לא כולל חוגי סטודיו
A15: 03_מרכז_כושר_נופים_מלוכלך.docx | B15: מרכז הכושר "נופים" | C15: מנוי בהו"ק | D15: 265 שח לחודש | E15: מינימום 3 חודשים
A16: 03_מרכז_כושר_נופים_מלוכלך.docx | B16: מרכז הכושר "נופים" | C16: מנוי גמלאי | D16: טרם נקבע | E16: יעודכן בקרוב
A17: 04_Neve_Sport_Center_bilingual.docx | B17: Neve Sport Center / מרכז הספורט "נווה" | C17: Single entry / כניסה חד פעמית | D17: NIS 62 | E17: Student / Soldier – NIS 55
A18: 04_Neve_Sport_Center_bilingual.docx | B18: Neve Sport Center / מרכז הספורט "נווה" | C18: 10-entry card / כרטיסייה | D18: NIS 520
A19: 04_Neve_Sport_Center_bilingual.docx | B19: Neve Sport Center / מרכז הספורט "נווה" | C19: Monthly membership / מנוי חודשי | D19: NIS 305
A20: 04_Neve_Sport_Center_bilingual.docx | B20: Neve Sport Center / מרכז הספורט "נווה" | C20: Standing order / הוראת קבע | D20: NIS 275 per month | E20: Minimum 3 months
A21: 05_מרכז_ספורט_מעיין_לפי_חוג.docx | B21: מרכז ספורט "מעיין" | C21: שיעור בודד (ללא מנוי) | D21: 45 ₪ | E21: בכפוף למקום פנוי
A22: 05_מרכז_ספורט_מעיין_לפי_חוג.docx | B22: מרכז ספורט "מעיין" | C22: כרטיסיית 10 שיעורים | D22: 390 ₪
A23: 05_מרכז_ספורט_מעיין_לפי_חוג.docx | B23: מרכז ספורט "מעיין" | C23: מנוי חודשי יחיד | D23: 295 ₪
A24: 05_מרכז_ספורט_מעיין_לפי_חוג.docx | B24: מרכז ספורט "מעיין" | C24: מנוי משפחתי (2 מבוגרים + 2 ילדים) | D24: 690 ₪ לחודש | E24: בהוראת קבע בלבד
A25: 05_מרכז_ספורט_מעיין_לפי_חוג.docx | B25: מרכז ספורט "מעיין" | C25: מנוי בוקר בלבד (עד 14:00) | D25: 215 ₪ לחודש
A26: 06_מרכז_ספורט_גלים_מקרי_קצה.docx | B26: מרכז הספורט "גלים" | C26: כניסה חד פעמית | D26: 68 ₪ | E26: בסניף ב' – 60 ₪
A27: 06_מרכז_ספורט_גלים_מקרי_קצה.docx | B27: מרכז הספורט "גלים" | C27: כרטיסייה ל-12 כניסות | D27: 620 ₪ | E27: תקפה בשני הסניפים
A28: 06_מרכז_ספורט_גלים_מקרי_קצה.docx | B28: מרכז הספורט "גלים" | C28: מנוי חודשי | D28: 329 ₪
A29: 06_מרכז_ספורט_גלים_מקרי_קצה.docx | B29: מרכז הספורט "גלים" | C29: מנוי בהוראת קבע | D29: 289 ₪ לחודש | E29: מינימום 3 חודשים; מנוי חוזר – 275 ₪
A30: 06_מרכז_ספורט_גלים_מקרי_קצה.docx | B30: מרכז הספורט "גלים" | C30: חוג ילדים (גילאי 6-14) | D30: 219 ₪ לחודש | E30: מחזור ב' נפתח ב-5.1.2026

Sheet שעות_פתיחה
A1: קובץ_מקור | B1: שם_המרכז | C1: ימים | D1: פתיחה | E1: סגירה | F1: הערות
A2: 01_מרכז_ספורט_הדס_בסיסי.docx | B2: מרכז הספורט "הדס" | C2: א'-ה' | D2: 06:00 | E2: 22:30 | F2: כל יום רביעי 13:00-15:00 סגור לתחזוקה.
A3: 01_מרכז_ספורט_הדס_בסיסי.docx | B3: מרכז הספורט "הדס" | C3: שישי | D3: 06:00 | E3: 16:30
A4: 01_מרכז_ספורט_הדס_בסיסי.docx | B4: מרכז הספורט "הדס" | C4: שבת | D4: 08:00 | E4: 16:00
A5: 02_מרכז_ספורט_אלונים_טבלה.docx | B5: מרכז ספורט "אלונים" | C5: א'-ה' | D5: 06:30 | E5: 22:00 | F5: הבריכה נסגרת חצי שעה לפני סגירת המרכז.
A6: 02_מרכז_ספורט_אלונים_טבלה.docx | B6: מרכז ספורט "אלונים" | C6: שישי | D6: 07:00 | E6: 15:00
A7: 02_מרכז_ספורט_אלונים_טבלה.docx | B7: מרכז ספורט "אלונים" | C7: שבת | D7: סגור | E7: סגור
A8: 03_מרכז_כושר_נופים_מלוכלך.docx | B8: מרכז הכושר "נופים" | C8: א-ה | D8: 06:00 | E8: 22:00 | F8: בחופשות ובחגים יתכנו שינויים – יש להתעדכן בעמוד הפייסבוק שלנו. | יום ב' 12:00 - 14:00 סגור
A9: 03_מרכז_כושר_נופים_מלוכלך.docx | B9: מרכז הכושר "נופים" | C9: ו | D9: 06:00 | E9: 16:00
A10: 03_מרכז_כושר_נופים_מלוכלך.docx | B10: מרכז הכושר "נופים" | C10: שבת | D10: 09:00 | E10: 15:00
A11: 04_Neve_Sport_Center_bilingual.docx | B11: Neve Sport Center / מרכז הספורט "נווה" | C11: Sunday-Thursday | D11: 6:00 AM | E11: 10:00 PM | F11: Pool closes 30 minutes before the center closes. | הבריכה נסגרת חצי שעה לפני סגירת המרכז.
A12: 04_Neve_Sport_Center_bilingual.docx | B12: Neve Sport Center / מרכז הספורט "נווה" | C12: Friday | D12: 6:00 AM | E12: 4:00 PM
A13: 04_Neve_Sport_Center_bilingual.docx | B13: Neve Sport Center / מרכז הספורט "נווה" | C13: Saturday | D13: 9:00 AM | E13: 5:00 PM
A14: 05_מרכז_ספורט_מעיין_לפי_חוג.docx | B14: מרכז ספורט "מעיין" | C14: א'-ה' | D14: 06:00 | E14: 23:00 | F14: בשעון חורף המרכז נסגר בימי שישי ושבת בשעה 15:00.
A15: 05_מרכז_ספורט_מעיין_לפי_חוג.docx | B15: מרכז ספורט "מעיין" | C15: שישי | D15: 06:30 | E15: 16:00
A16: 05_מרכז_ספורט_מעיין_לפי_חוג.docx | B16: מרכז ספורט "מעיין" | C16: שבת | D16: 08:30 | E16: 17:00
A17: 06_מרכז_ספורט_גלים_מקרי_קצה.docx | B17: מרכז הספורט "גלים" | C17: א'-ה' (שעון קיץ) | D17: 05:45 | E17: 23:00 | F17: ערב חג: 06:00-13:00. בחג – סגור. | בתשעה באב ובערב יום כיפור המרכז סגור כל היום. | סניף ב' סגור בימי שישי.
A18: 06_מרכז_ספורט_גלים_מקרי_קצה.docx | B18: מרכז הספורט "גלים" | C18: א'-ה' (שעון חורף) | D18: 06:00 | E18: 22:00
A19: 06_מרכז_ספורט_גלים_מקרי_קצה.docx | B19: מרכז הספורט "גלים" | C19: שישי | D19: 06:00 | E19: 16:00
A20: 06_מרכז_ספורט_גלים_מקרי_קצה.docx | B20: מרכז הספורט "גלים" | C20: שבת | D20: 09:00 | E20: 17:00

Sheet מקור_פענוח_גולמי
A1: מרכז הספורט 'יובלים' פיליפ ליאון (הקובץ שהועלה)
A2: פענוח גולמי מתוך ה-PDF המקורי. מבנה הטבלה ב-PDF אינו חד-משמעי – שיוך היום מסומן 'לאימות' היכן שלא ודאי.
A4: יום | B4: שעת_התחלה | C4: שם_החוג | D4: מדריך | E4: אולם | F4: קהל_יעד | G4: רמת_ודאות
A5: ראשון | B5: 08:00 | C5: התעמלות מתונה | D5: חיה | E5: אולם ספורט | G5: ודאי
A6: שני | B6: 07:40 | C6: התעמלות מתונה | D6: תמר | E6: אולם ספורט | G6: ודאי
A7: שלישי | B7: 07:40 | C7: התעמלות מתונה | D7: אורה | E7: אולם ספורט | G7: ודאי
A8: רביעי | B8: 07:40 | C8: התעמלות מתונה | D8: תמר | E8: אולם ספורט | G8: ודאי
A9: חמישי | B9: 07:40 | C9: התעמלות מתונה | D9: אורה | E9: אולם ספורט | G9: ודאי
A10: שישי | B10: 08:30 | C10: פילאטיס | D10: רויטל | E10: ספורט כייף | G10: ודאי
A11: ראשון | B11: 09:00 | C11: עיצוב וחיזוק | D11: תמר | E11: אולם ספורט | G11: בקובץ מופיע 9.00
A12: שני | B12: 08:30 | C12: פילאטיס | D12: תמר | E12: ספורט כייף | F12: גם לגברים | G12: ודאי
A13: שלישי | B13: 09:00 | C13: עיצוב וחיזוק | D13: תמר | E13: אולם ספורט | G13: ודאי
A14: רביעי | B14: 09:00 | C14: עיצוב וחיזוק | D14: תמר | E14: אולם ספורט | F14: גם לגברים | G14: ודאי
A15: חמישי | B15: 08:30 | C15: פילאטיס | D15: אנה | E15: ספורט כייף | F15: גם לגברים | G15: ודאי
A16: שישי | B16: 08:30 | C16: ספינינג | D16: גל | E16: חדר ספינינג | F16: גם לגברים | G16: כולל הסבר למתחילים 08:15-08:30
A17: ראשון | B17: 09:40 | C17: עיצוב | D17: אנה | E17: סטודיו תחתון | G17: ודאי
A18: שני | B18: 10:00 | C18: יוגה | D18: תניא | E18: ספורט כייף | F18: גם לגברים | G18: ודאי
A19: שלישי | B19: 09:40 | C19: עיצוב | D19: אנה | E19: סטודיו תחתון | G19: ודאי
A20: רביעי | B20: 09:30 | C20: פילאטיס | D20: רויטל | E20: ספורט כייף | F20: גם לגברים | G20: ודאי
A21: חמישי | B21: 09:15 | C21: התעמלות במים | D21: זויה | E21: בריכה | G21: אולם לא צוין במקור
A22: לאימות | B22: 10:30 | C22: פלדנקרייז | D22: הילה | E22: ספורט כייף | G22: שיוך יום לא ודאי
A23: ראשון | B23: 18:05 | C23: עיצוב קל | D23: יעל | E23: סטודיו תחתון | G23: ודאי
A24: ראשון | B24: 19:05 | C24: עיצוב דינמי | D24: יעל | E24: סטודיו תחתון | F24: גם לגברים | G24: ודאי
A25: שני | B25: 16:45 | C25: פילאטיס | D25: זויה | E25: סטודיו תחתון | G25: ודאי
A26: שני | B26: 17:45 | C26: עיצוב | D26: זויה | E26: סטודיו תחתון | F26: גם לגברים | G26: ודאי
A27: שלישי | B27: 17:30 | C27: פילאטיס | D27: תמר | E27: סטודיו עליון | G27: ודאי
A28: רביעי | B28: 18:05 | C28: פילאטיס | D28: יעל | E28: סטודיו תחתון | F28: גם לגברים | G28: שיוך יום לאימות
A29: לאימות | B29: 19:10 | C29: זומבה | D29: אינדי | E29: סטודיו עליון | F29: גם לגברים | G29: שיוך יום לא ודאי
A30: לאימות | B30: 18:30 | C30: יוגה | D30: משה | E30: ספורט כייף | F30: גם לגברים | G30: שיוך יום לא ודאי
A31: לאימות | B31: 19:10 | C31: יוגה | D31: תניא | E31: ספורט כייף | F31: גם לגברים | G31: שיוך יום לא ודאי
